Workbook

Sheet Numbers
A1: State | B1: 2000 | C1: 2004 | D1: 2008 | E1: 2012 | F1: 2016 | G1: 2020 | H1: 2024 | I1: Notes
A2: Alabama | B2: 1 | C2: 1 | D2: 1 | E2: 1 | F2: 2 | G2: 2 | H2: 2 | M2: Legend - Availability of Voter Registration Options in Presidential Elections, 2000-2024
A3: Alaska | B3: 1 | C3: 1 | D3: 1 | E3: 1 | F3: 2 | G3: 4 | H3: 4 | M3: 1 | N3: Traditional registration only (+ NVRA reqs.)
A4: Arizona | B4: 1 | C4: 2 | D4: 2 | E4: 2 | F4: 2 | G4: 2 | H4: 2 | M4: 2 | N4: OVR only
A5: Arkansas | B5: 1 | C5: 1 | D5: 1 | E5: 1 | F5: 1 | G5: 1 | H5: 1 | M5: 3 | N5: SDR only
A6: California | B6: 1 | C6: 1 | D6: 1 | E6: 2 | F6: 2 | G6: 6 | H6: 6 | M6: 4 | N6: OVR & AVR
A7: Colorado | B7: 1 | C7: 1 | D7: 1 | E7: 2 | F7: 5 | G7: 6 | H7: 6 | M7: 5 | N7: OVR & SDR
A8: Connecticut | B8: 1 | C8: 1 | D8: 1 | E8: 1 | F8: 6 | G8: 6 | H8: 6 | I8: AVR implementation year based on convo with KS | M8: 6 | N8: OVR, AVR, and SDR
A9: D.C. | B9: 1 | C9: 1 | D9: 1 | E9: 3 | F9: 5 | G9: 6 | H9: 6
A10: Delaware | B10: 1 | C10: 1 | D10: 1 | E10: 1 | F10: 2 | G10: 2 | H10: 4
A11: Florida | B11: 1 | C11: 1 | D11: 1 | E11: 1 | F11: 1 | G11: 2 | H11: 2
A12: Georgia | B12: 1 | C12: 1 | D12: 1 | E12: 1 | F12: 4 | G12: 4 | H12: 4
A13: Hawaii | B13: 1 | C13: 1 | D13: 1 | E13: 1 | F13: 5 | G13: 5 | H13: 6 | I13: Hawaii has AVR according to NCSL
A14: Idaho | B14: 3 | C14: 3 | D14: 3 | E14: 3 | F14: 3 | G14: 5 | H14: 5
A15: Illinois | B15: 1 | C15: 1 | D15: 3 | E15: 3 | F15: 5 | G15: 6 | H15: 6
A16: Indiana | B16: 1 | C16: 1 | D16: 1 | E16: 2 | F16: 2 | G16: 2 | H16: 2
A17: Iowa | B17: 1 | C17: 1 | D17: 3 | E17: 3 | F17: 5 | G17: 5 | H17: 5
A18: Kansas | B18: 1 | C18: 1 | D18: 1 | E18: 2 | F18: 2 | G18: 2 | H18: 2
A19: Kentucky | B19: 1 | C19: 1 | D19: 1 | E19: 1 | F19: 2 | G19: 2 | H19: 2
A20: Louisiana | B20: 1 | C20: 1 | D20: 1 | E20: 2 | F20: 2 | G20: 2 | H20: 2
A21: Maine | B21: 3 | C21: 3 | D21: 3 | E21: 3 | F21: 3 | G21: 3 | H21: 6
A22: Maryland | B22: 1 | C22: 1 | D22: 1 | E22: 2 | F22: 5 | G22: 6 | H22: 6 | I22: AVR Implementation year 2019 according to NCSL
A23: Massachusetts | B23: 1 | C23: 1 | D23: 1 | E23: 1 | F23: 2 | G23: 4 | H23: 4 | I23: No SDR according to NCSL
A24: Michigan | B24: 1 | C24: 1 | D24: 1 | E24: 1 | F24: 1 | G24: 6 | H24: 6
A25: Minnesota | B25: 3 | C25: 3 | D25: 3 | E25: 3 | F25: 5 | G25: 5 | H25: 6
A26: Mississippi | B26: 1 | C26: 1 | D26: 1 | E26: 1 | F26: 1 | G26: 1 | H26: 1
A27: Missouri | B27: 1 | C27: 1 | D27: 1 | E27: 1 | F27: 2 | G27: 2 | H27: 2
A28: Montana | B28: 1 | C28: 1 | D28: 3 | E28: 3 | F28: 3 | G28: 3 | H28: 3
A29: Nebraska | B29: 1 | C29: 1 | D29: 1 | E29: 1 | F29: 2 | G29: 2 | H29: 2 | I29: No SDR according to NCSL
A30: Nevada | B30: 1 | C30: 1 | D30: 1 | E30: 2 | F30: 2 | G30: 6 | H30: 6
A31: New Hampshire | B31: 3 | C31: 3 | D31: 3 | E31: 3 | F31: 3 | G31: 3 | H31: 3
A32: New Jersey | B32: 1 | C32: 1 | D32: 1 | E32: 1 | F32: 1 | G32: 4 | H32: 4
A33: New Mexico | B33: 1 | C33: 1 | D33: 1 | E33: 1 | F33: 2 | G33: 6 | H33: 6 | I33: AVR Implementation in 2020 according to NCSL
A34: New York | B34: 1 | C34: 1 | D34: 1 | E34: 1 | F34: 1 | G34: 1 | H34: 5
A35: North Carolina | B35: 1 | C35: 1 | D35: 3 | E35: 3 | F35: 3 | G35: 5 | H35: 5
A36: North Dakota | B36: 3 | C36: 3 | D36: 3 | E36: 3 | F36: 3 | G36: 3 | H36: 3
A37: Ohio | B37: 1 | C37: 1 | D37: 3 | E37: 3 | F37: 1 | G37: 2 | H37: 2
A38: Oklahoma | B38: 1 | C38: 1 | D38: 1 | E38: 1 | F38: 1 | G38: 1 | H38: 2
A39: Oregon | B39: 1 | C39: 1 | D39: 1 | E39: 2 | F39: 4 | G39: 4 | H39: 4
A40: Pennsylvania | B40: 1 | C40: 1 | D40: 1 | E40: 1 | F40: 2 | G40: 2 | H40: 4
...

Sheet Colors & Symbols
A1: State | B1: 2000 | C1: 2004 | D1: 2008 | E1: 2012 | F1: 2016 | G1: 2020 | H1: 2024 | I1: Lingering Q's
A2: Alabama | B2: α | C2: α | D2: α | E2: α | F2: β | G2: β | H2: β | M2: Legend - Availability of Voter Registration Options in Presidential Elections, 2000-2024
A3: Alaska | B3: α | C3: α | D3: α | E3: α | F3: β | G3: δ | H3: δ | M3: α | N3: Traditional registration only (+ NVRA reqs.)
A4: Arizona | B4: α | C4: β | D4: β | E4: β | F4: β | G4: β | H4: β | M4: β | N4: OVR only
A5: Arkansas | B5: α | C5: α | D5: α | E5: α | F5: α | G5: α | H5: α | M5: γ | N5: SDR only
A6: California | B6: α | C6: α | D6: α | E6: β | F6: β | G6: ζ | H6: ζ | M6: δ | N6: OVR & AVR
A7: Colorado | B7: α | C7: α | D7: α | E7: β | F7: ε | G7: ζ | H7: ζ | M7: ε | N7: OVR & SDR
A8: Connecticut | B8: α | C8: α | D8: α | E8: α | F8: ζ | G8: ζ | H8: ζ | M8: ζ | N8: OVR, AVR, and SDR
A9: D.C. | B9: α | C9: α | D9: α | E9: γ | F9: ε | G9: ζ | H9: ζ
A10: Delaware | B10: α | C10: α | D10: α | E10: α | F10: β | G10: β | H10: δ
A11: Florida | B11: α | C11: α | D11: α | E11: α | F11: α | G11: β | H11: β
A12: Georgia | B12: α | C12: α | D12: α | E12: α | F12: δ | G12: δ | H12: δ
A13: Hawaii | B13: α | C13: α | D13: α | E13: α | F13: ε | G13: ε | H13: ζ
A14: Idaho | B14: γ | C14: γ | D14: γ | E14: γ | F14: γ | G14: ε | H14: ε
A15: Illinois | B15: α | C15: α | D15: γ | E15: γ | F15: ε | G15: ζ | H15: ζ
A16: Indiana | B16: α | C16: α | D16: α | E16: β | F16: β | G16: β | H16: β
A17: Iowa | B17: α | C17: α | D17: γ | E17: γ | F17: ε | G17: ε | H17: ε
A18: Kansas | B18: α | C18: α | D18: α | E18: β | F18: β | G18: β | H18: β
A19: Kentucky | B19: α | C19: α | D19: α | E19: α | F19: β | G19: β | H19: β
A20: Louisiana | B20: α | C20: α | D20: α | E20: β | F20: β | G20: β | H20: β
A21: Maine | B21: γ | C21: γ | D21: γ | E21: γ | F21: γ | G21: γ | H21: ζ
A22: Maryland | B22: α | C22: α | D22: α | E22: β | F22: ε | I22: AVR Implementation - has it happened?
A23: Massachusetts | B23: α | C23: α | D23: α | E23: α | F23: β | G23: δ | H23: δ | I23: Does MA have SDR?
A24: Michigan | B24: α | C24: α | D24: α | E24: α | F24: α | G24: ζ | H24: ζ
A25: Minnesota | B25: γ | C25: γ | D25: γ | E25: γ | F25: ε | G25: ε | H25: ζ
A26: Mississippi | B26: α | C26: α | D26: α | E26: α | F26: α | G26: α | H26: α
A27: Missouri | B27: α | C27: α | D27: α | E27: α | F27: β | G27: β | H27: β
A28: Montana | B28: α | C28: α | D28: γ | E28: γ | F28: γ | G28: γ | H28: γ
A29: Nebraska | B29: α | C29: α | D29: α | E29: α | F29: ε | G29: ε | H29: ε | I29: When was SDR implemnted? Pre-2014? (depending on state self categorization)
A30: Nevada | B30: α | C30: α | D30: α | E30: β | F30: β | G30: ζ | H30: ζ
A31: New Hampshire | B31: γ | C31: γ | D31: γ | E31: γ | F31: γ | G31: γ | H31: γ
A32: New Jersey | B32: α | C32: α | D32: α | E32: α | F32: α | G32: δ | H32: δ
A33: New Mexico | B33: α | C33: α | D33: α | E33: α | F33: β | G33: ε | H33: ζ | I33: AVR Implementation - 2020 or 2025?
A34: New York | B34: α | C34: α | D34: α | E34: α | F34: α | G34: α | H34: ε
A35: North Carolina | B35: α | C35: α | D35: γ | E35: γ | F35: γ | G35: ε | H35: ε
A36: North Dakota | B36: γ | C36: γ | D36: γ | E36: γ | F36: γ | G36: γ | H36: γ | I36: ******
A37: Ohio | B37: α | C37: α | D37: γ | E37: γ | F37: α | G37: β | H37: β
A38: Oklahoma | B38: α | C38: α | D38: α | E38: α | F38: α | G38: α | H38: β
A39: Oregon | B39: α | C39: α | D39: α | E39: β | F39: δ | G39: δ | H39: δ
A40: Pennsylvania | B40: α | C40: α | D40: α | E40: α | F40: β | G40: β | H40: δ
...

Sheet Sample Data
A1: State | B1: 2000 | C1: 2004 | D1: 2008 | E1: 2012 | F1: 2016 | G1: 2020 | H1: 2024
A2: Alabama | B2: 1 | C2: 1 | D2: 1 | E2: 1 | F2: 2 | G2: 2 | H2: 2 | L2: Legend - Availability of Voter Registration Options in Presidential Elections, 2000-2024
A3: Alaska | B3: 1 | C3: 1 | D3: 1 | E3: 1 | F3: 2 | G3: 5 | H3: 5 | L3: 1 | M3: Traditional registration only (+ NVRA reqs.)
A4: Arizona | B4: 1 | C4: 2 | D4: 2 | E4: 2 | F4: 2 | G4: 2 | H4: 2 | L4: 2 | M4: OVR only
A5: Arkansas | B5: 1 | C5: 1 | D5: 1 | E5: 1 | F5: 1 | G5: 1 | H5: 1 | L5: 3 | M5: AVR only (N/A)
A6: California | B6: 1 | C6: 1 | D6: 1 | E6: 2 | F6: 2 | G6: 8 | H6: 8 | L6: 4 | M6: SDR only
A7: Colorado | B7: 1 | C7: 1 | D7: 1 | E7: 2 | F7: 6 | G7: 8 | H7: 8 | L7: 5 | M7: OVR & AVR
A8: Connecticut | B8: 1 | C8: 1 | D8: 1 | E8: 1 | F8: 8 | G8: 8 | H8: 8 | L8: 6 | M8: OVR & SDR
A9: D.C. | B9: 1 | C9: 1 | D9: 1 | E9: 4 | F9: 6 | G9: 8 | H9: 8 | L9: 7 | M9: SDR & AVR (N/A)
A10: Delaware | B10: 1 | C10: 1 | D10: 1 | E10: 1 | F10: 2 | G10: 2 | H10: 5 | L10: 8 | M10: OVR, AVR, and SDR
A11: Florida | B11: 1 | C11: 1 | D11: 1 | E11: 1 | F11: 1 | G11: 2 | H11: 2
A12: Georgia | B12: 1 | C12: 1 | D12: 1 | E12: 1 | F12: 5 | G12: 5 | H12: 5
A13: Hawaii | B13: 1 | C13: 1 | D13: 1 | E13: 1 | F13: 6 | G13: 6 | H13: 8
A14: Idaho | B14: 4 | C14: 4 | D14: 4 | E14: 4 | F14: 4 | G14: 6 | H14: 6
A15: Illinois | B15: 1 | C15: 1 | D15: 4 | E15: 4 | F15: 6 | G15: 8 | H15: 8
A16: Indiana | B16: 1 | C16: 1 | D16: 1 | E16: 2 | F16: 2 | G16: 2 | H16: 2
A17: Iowa | B17: 1 | C17: 1 | D17: 4 | E17: 4 | F17: 6 | G17: 6 | H17: 6
A18: Kansas | B18: 1 | C18: 1 | D18: 1 | E18: 2 | F18: 2 | G18: 2 | H18: 2
A19: Kentucky | B19: 1 | C19: 1 | D19: 1 | E19: 1 | F19: 2 | G19: 2 | H19: 2
A20: Louisiana | B20: 1 | C20: 1 | D20: 1 | E20: 2 | F20: 2 | G20: 2 | H20: 2
A21: Maine | B21: 4 | C21: 4 | D21: 4 | E21: 4 | F21: 4 | G21: 4 | H21: 8
A22: Maryland | B22: 1 | C22: 1 | D22: 1 | E22: 2 | F22: 6 | G22: 8 | H22: 8
... A52: Wyoming | B52: 4 | C52: 4 | D52: 4 | E52: 4 | F52: 4 | G52: 4 | H52: 4

Sheet LongData
A1: State | B1: Year | C1: Value | D1: HexRow | E1: HexColumns | F1: StateAbb
A2: Alabama | B2: 2000 | C2: 1 | D2: =VLOOKUP(A2,hex!$A$1:$D$52,2,FALSE) -> 6 | E2: =VLOOKUP(A2,hex!$A$1:$D$52,3,FALSE) -> 7.5 | F2: =VLOOKUP(A2,hex!$A$1:$D$52,4,FALSE) -> AL
A3: Alabama | B3: 2004 | C3: 1 | D3: =VLOOKUP(A3,hex!$A$1:$D$52,2,FALSE) -> 6 | E3: =VLOOKUP(A3,hex!$A$1:$D$52,3,FALSE) -> 7.5 | F3: =VLOOKUP(A3,hex!$A$1:$D$52,4,FALSE) -> AL
A4: Alabama | B4: 2008 | C4: 1 | D4: =VLOOKUP(A4,hex!$A$1:$D$52,2,FALSE) -> 6 | E4: =VLOOKUP(A4,hex!$A$1:$D$52,3,FALSE) -> 7.5 | F4: =VLOOKUP(A4,hex!$A$1:$D$52,4,FALSE) -> AL
A5: Alabama | B5: 2012 | C5: 1 | D5: =VLOOKUP(A5,hex!$A$1:$D$52,2,FALSE) -> 6 | E5: =VLOOKUP(A5,hex!$A$1:$D$52,3,FALSE) -> 7.5 | F5: =VLOOKUP(A5,hex!$A$1:$D$52,4,FALSE) -> AL
A6: Alabama | B6: 2016 | C6: 2 | D6: =VLOOKUP(A6,hex!$A$1:$D$52,2,FALSE) -> 6 | E6: =VLOOKUP(A6,hex!$A$1:$D$52,3,FALSE) -> 7.5 | F6: =VLOOKUP(A6,hex!$A$1:$D$52,4,FALSE) -> AL
A7: Alabama | B7: 2020 | C7: 2 | D7: =VLOOKUP(A7,hex!$A$1:$D$52,2,FALSE) -> 6 | E7: =VLOOKUP(A7,hex!$A$1:$D$52,3,FALSE) -> 7.5 | F7: =VLOOKUP(A7,hex!$A$1:$D$52,4,FALSE) -> AL
A8: Alabama | B8: 2024 | C8: 2 | D8: =VLOOKUP(A8,hex!$A$1:$D$52,2,FALSE) -> 6 | E8: =VLOOKUP(A8,hex!$A$1:$D$52,3,FALSE) -> 7.5 | F8: =VLOOKUP(A8,hex!$A$1:$D$52,4,FALSE) -> AL
A9: Alaska | B9: 2000 | C9: 1 | D9: =VLOOKUP(A9,hex!$A$1:$D$52,2,FALSE) -> 0 | E9: =VLOOKUP(A9,hex!$A$1:$D$52,3,FALSE) -> 0.5 | F9: =VLOOKUP(A9,hex!$A$1:$D$52,4,FALSE) -> AK
A10: Alaska | B10: 2004 | C10: 1 | D10: =VLOOKUP(A10,hex!$A$1:$D$52,2,FALSE) -> 0 | E10: =VLOOKUP(A10,hex!$A$1:$D$52,3,FALSE) -> 0.5 | F10: =VLOOKUP(A10,hex!$A$1:$D$52,4,FALSE) -> AK
A11: Alaska | B11: 2008 | C11: 1 | D11: =VLOOKUP(A11,hex!$A$1:$D$52,2,FALSE) -> 0 | E11: =VLOOKUP(A11,hex!$A$1:$D$52,3,FALSE) -> 0.5 | F11: =VLOOKUP(A11,hex!$A$1:$D$52,4,FALSE) -> AK
A12: Alaska | B12: 2012 | C12: 1 | D12: =VLOOKUP(A12,hex!$A$1:$D$52,2,FALSE) -> 0 | E12: =VLOOKUP(A12,hex!$A$1:$D$52,3,FALSE) -> 0.5 | F12: =VLOOKUP(A12,hex!$A$1:$D$52,4,FALSE) -> AK
A13: Alaska | B13: 2016 | C13: 2 | D13: =VLOOKUP(A13,hex!$A$1:$D$52,2,FALSE) -> 0 | E13: =VLOOKUP(A13,hex!$A$1:$D$52,3,FALSE) -> 0.5 | F13: =VLOOKUP(A13,hex!$A$1:$D$52,4,FALSE) -> AK
... A358: Wyoming | B358: 2024 | C358: 3 | D358: =VLOOKUP(A358,hex!$A$1:$D$52,2,FALSE) -> 3 | E358: =VLOOKUP(A358,hex!$A$1:$D$52,3,FALSE) -> 3 | F358: =VLOOKUP(A358,hex!$A$1:$D$52,4,FALSE) -> WY

Sheet hex
A1: State | B1: Row | C1: Column | D1: Abb
A2: Alaska | B2: 0 | C2: 0.5 | D2: AK
A3: Alabama | B3: 6 | C3: 7.5 | D3: AL
A4: Arkansas | B4: 5 | C4: 6 | D4: AR
A5: Arizona | B5: 5 | C5: 3 | D5: AZ
A6: California | B6: 5 | C6: 2 | D6: CA
A7: Colorado | B7: 4 | C7: 3.5 | D7: CO
A8: Connecticut | B8: 3 | C8: 11 | D8: CT
A9: D.C. | B9: 4 | C9: 10.5 | D9: DC
A10: Delaware | B10: 4 | C10: 9.5 | D10: DE
A11: Florida | B11: 8 | C11: 8.5 | D11: FL
A12: Georgia | B12: 7 | C12: 8 | D12: GA
A13: Hawaii | B13: 8 | C13: 0.5 | D13: HI
... A52: Wyoming | B52: 3 | C52: 3 | D52: WY
